2025-02-27 01:45:15 [INFO] Question: Which are the top 5 countries by sales?
2025-02-27 01:45:16 [INFO] Running PandasAI with bamboo_llm LLM...
2025-02-27 01:45:16 [INFO] Prompt ID: a7fdf88b-aeca-42cc-a584-b9dc72ed4906
2025-02-27 01:45:16 [INFO] Executing Pipeline: GenerateChatPipeline
2025-02-27 01:45:16 [INFO] Executing Step 0: ValidatePipelineInput
2025-02-27 01:45:16 [INFO] Executing Step 1: CacheLookup
2025-02-27 01:45:16 [INFO] Executing Step 2: PromptGeneration
2025-02-27 01:45:26 [ERROR] Request failed: Traceback (most recent call last):
  File "e:\packages\Anaconda3\envs\pandas_ai\Lib\site-packages\requests\models.py", line 974, in json
    return complexjson.loads(self.text, **kwargs)
           ^^^^^^^^^^^^^^^^^^^^^^^^^^^^^^^^^^^^^^
  File "e:\packages\Anaconda3\envs\pandas_ai\Lib\json\__init__.py", line 346, in loads
    return _default_decoder.decode(s)
           ^^^^^^^^^^^^^^^^^^^^^^^^^^
  File "e:\packages\Anaconda3\envs\pandas_ai\Lib\json\decoder.py", line 337, in decode
    obj, end = self.raw_decode(s, idx=_w(s, 0).end())
               ^^^^^^^^^^^^^^^^^^^^^^^^^^^^^^^^^^^^^^
  File "e:\packages\Anaconda3\envs\pandas_ai\Lib\json\decoder.py", line 355, in raw_decode
    raise JSONDecodeError("Expecting value", s, err.value) from None
json.decoder.JSONDecodeError: Expecting value: line 1 column 1 (char 0)

During handling of the above exception, another exception occurred:

Traceback (most recent call last):
  File "e:\packages\Anaconda3\envs\pandas_ai\Lib\site-packages\pandasai\helpers\request.py", line 69, in make_request
    data = response.json()
           ^^^^^^^^^^^^^^^
  File "e:\packages\Anaconda3\envs\pandas_ai\Lib\site-packages\requests\models.py", line 978, in json
    raise RequestsJSONDecodeError(e.msg, e.doc, e.pos)
requests.exceptions.JSONDecodeError: Expecting value: line 1 column 1 (char 0)

2025-02-27 01:45:26 [INFO] Querying without using training data.
2025-02-27 01:45:36 [ERROR] Request failed: Traceback (most recent call last):
  File "e:\packages\Anaconda3\envs\pandas_ai\Lib\site-packages\requests\models.py", line 974, in json
    return complexjson.loads(self.text, **kwargs)
           ^^^^^^^^^^^^^^^^^^^^^^^^^^^^^^^^^^^^^^
  File "e:\packages\Anaconda3\envs\pandas_ai\Lib\json\__init__.py", line 346, in loads
    return _default_decoder.decode(s)
           ^^^^^^^^^^^^^^^^^^^^^^^^^^
  File "e:\packages\Anaconda3\envs\pandas_ai\Lib\json\decoder.py", line 337, in decode
    obj, end = self.raw_decode(s, idx=_w(s, 0).end())
               ^^^^^^^^^^^^^^^^^^^^^^^^^^^^^^^^^^^^^^
  File "e:\packages\Anaconda3\envs\pandas_ai\Lib\json\decoder.py", line 355, in raw_decode
    raise JSONDecodeError("Expecting value", s, err.value) from None
json.decoder.JSONDecodeError: Expecting value: line 1 column 1 (char 0)

During handling of the above exception, another exception occurred:

Traceback (most recent call last):
  File "e:\packages\Anaconda3\envs\pandas_ai\Lib\site-packages\pandasai\helpers\request.py", line 69, in make_request
    data = response.json()
           ^^^^^^^^^^^^^^^
  File "e:\packages\Anaconda3\envs\pandas_ai\Lib\site-packages\requests\models.py", line 978, in json
    raise RequestsJSONDecodeError(e.msg, e.doc, e.pos)
requests.exceptions.JSONDecodeError: Expecting value: line 1 column 1 (char 0)

2025-02-27 01:45:37 [INFO] Querying without using training docs.
2025-02-27 01:45:37 [INFO] Using prompt: <dataframe>
dfs[0]:10x2
country,revenue
Australia,2600
China,2900
Germany,7000
</dataframe>




Update this initial code:
```python
# TODO: import the required dependencies
import pandas as pd

# Write code here

# Declare result var: 
type (possible values "string", "number", "dataframe", "plot"). Examples: { "type": "string", "value": f"The highest salary is {highest_salary}." } or { "type": "number", "value": 125 } or { "type": "dataframe", "value": pd.DataFrame({...}) } or { "type": "plot", "value": "temp_chart.png" }

```







### QUERY
 Which are the top 5 countries by sales?

Variable `dfs: list[pd.DataFrame]` is already declared.

At the end, declare "result" variable as a dictionary of type and value.

If you are asked to plot a chart, use "matplotlib" for charts, save as png.


Generate python code and return full updated code:
2025-02-27 01:45:37 [INFO] Executing Step 3: CodeGenerator
2025-02-27 01:45:47 [ERROR] Request failed: Traceback (most recent call last):
  File "e:\packages\Anaconda3\envs\pandas_ai\Lib\site-packages\requests\models.py", line 974, in json
    return complexjson.loads(self.text, **kwargs)
           ^^^^^^^^^^^^^^^^^^^^^^^^^^^^^^^^^^^^^^
  File "e:\packages\Anaconda3\envs\pandas_ai\Lib\json\__init__.py", line 346, in loads
    return _default_decoder.decode(s)
           ^^^^^^^^^^^^^^^^^^^^^^^^^^
  File "e:\packages\Anaconda3\envs\pandas_ai\Lib\json\decoder.py", line 337, in decode
    obj, end = self.raw_decode(s, idx=_w(s, 0).end())
               ^^^^^^^^^^^^^^^^^^^^^^^^^^^^^^^^^^^^^^
  File "e:\packages\Anaconda3\envs\pandas_ai\Lib\json\decoder.py", line 355, in raw_decode
    raise JSONDecodeError("Expecting value", s, err.value) from None
json.decoder.JSONDecodeError: Expecting value: line 1 column 1 (char 0)

During handling of the above exception, another exception occurred:

Traceback (most recent call last):
  File "e:\packages\Anaconda3\envs\pandas_ai\Lib\site-packages\pandasai\helpers\request.py", line 69, in make_request
    data = response.json()
           ^^^^^^^^^^^^^^^
  File "e:\packages\Anaconda3\envs\pandas_ai\Lib\site-packages\requests\models.py", line 978, in json
    raise RequestsJSONDecodeError(e.msg, e.doc, e.pos)
requests.exceptions.JSONDecodeError: Expecting value: line 1 column 1 (char 0)

2025-02-27 01:45:47 [ERROR] Pipeline failed on step 3: Request failed: Expecting value: line 1 column 1 (char 0)
